Workbook

Sheet Podsumowanie
A1: Wniosek o płatność – PODSUMOWANIE (PDF str. 27–34)
A2: Dochód (str. 26): kwota pomniejszająca wydatki kwalifikowalne = 0,00; kwota pomniejszająca dofinansowanie = 0,00. Dane wpisane z PDF (niebieski); kolumny G–H to formuły.
A4: Pozycja budżetowa | B4: Rodzaj | C4: Wydatki bieżące | D4: Wydatki narastająco | E4: Wydatki w projekcie | F4: % realizacji (PDF) | G4: % realizacji (wyliczone) | H4: Różnica %
A5: Zadanie 1. Opracowanie narzędzi i przeprowadzenie badań w celu parametryzacji obrazów - B + R | B5: Ogółem | C5: 0 | D5: 807424.87 | E5: 868383.93 | F5: 92.98 | G5: =IF(E5=0,0,D5/E5*100) -> 92.980172 | H5: =ROUND(G5-F5,2) -> 0
B6: Kwalifikowalne | C6: 0 | D6: 807424.87 | E6: 868383.93 | F6: 92.98 | G6: =IF(E6=0,0,D6/E6*100) -> 92.980172 | H6: =ROUND(G6-F6,2) -> 0
B7: Dofinansowanie | C7: 0 | D7: 645939.9 | E7: 694707.14 | F7: 92.98 | G7: =IF(E7=0,0,D7/E7*100) -> 92.980173 | H7: =ROUND(G7-F7,2) -> 0
A8: 1.1 Personel projektu - Ekspert AI | B8: Ogółem | C8: 0 | D8: 277000 | E8: 277000 | F8: 100 | G8: =IF(E8=0,0,D8/E8*100) -> 100 | H8: =ROUND(G8-F8,2) -> 0
B9: Kwalifikowalne | C9: 0 | D9: 277000 | E9: 277000 | F9: 100 | G9: =IF(E9=0,0,D9/E9*100) -> 100 | H9: =ROUND(G9-F9,2) -> 0
B10: Dofinansowanie | C10: 0 | D10: 221600 | E10: 221600 | F10: 100 | G10: =IF(E10=0,0,D10/E10*100) -> 100 | H10: =ROUND(G10-F10,2) -> 0
A11: 1.2 Personel projektu - Big Data Engineer | B11: Ogółem | C11: 0 | D11: 94300 | E11: 94300 | F11: 100 | G11: =IF(E11=0,0,D11/E11*100) -> 100 | H11: =ROUND(G11-F11,2) -> 0
B12: Kwalifikowalne | C12: 0 | D12: 94300 | E12: 94300 | F12: 100 | G12: =IF(E12=0,0,D12/E12*100) -> 100 | H12: =ROUND(G12-F12,2) -> 0
B13: Dofinansowanie | C13: 0 | D13: 75440 | E13: 75440 | F13: 100 | G13: =IF(E13=0,0,D13/E13*100) -> 100 | H13: =ROUND(G13-F13,2) -> 0
A14: 1.3 Personel projektu - Ekspert ds. psychometrii | B14: Ogółem | C14: 0 | D14: 121994.98 | E14: 135550 | F14: 90 | G14: =IF(E14=0,0,D14/E14*100) -> 89.999985 | H14: =ROUND(G14-F14,2) -> 0
B15: Kwalifikowalne | C15: 0 | D15: 121994.98 | E15: 135550 | F15: 90 | G15: =IF(E15=0,0,D15/E15*100) -> 89.999985 | H15: =ROUND(G15-F15,2) -> 0
B16: Dofinansowanie | C16: 0 | D16: 97595.98 | E16: 108440 | F16: 90 | G16: =IF(E16=0,0,D16/E16*100) -> 89.999982 | H16: =ROUND(G16-F16,2) -> 0
A17: 1.4 Personel projektu - Senior Developer | B17: Ogółem | C17: 0 | D17: 50828.54 | E17: 51562.5 | F17: 98.58 | G17: =IF(E17=0,0,D17/E17*100) -> 98.576562 | H17: =ROUND(G17-F17,2) -> 0
B18: Kwalifikowalne | C18: 0 | D18: 50828.54 | E18: 51562.5 | F18: 98.58 | G18: =IF(E18=0,0,D18/E18*100) -> 98.576562 | H18: =ROUND(G18-F18,2) -> 0
B19: Dofinansowanie | C19: 0 | D19: 40662.83 | E19: 41250 | F19: 98.58 | G19: =IF(E19=0,0,D19/E19*100) -> 98.576558 | H19: =ROUND(G19-F19,2) -> 0
A20: 1.5 Personel projektu - Automation QA Engineer | B20: Ogółem | C20: 0 | D20: 34550.27 | E20: 37200 | F20: 92.88 | G20: =IF(E20=0,0,D20/E20*100) -> 92.87707 | H20: =ROUND(G20-F20,2) -> 0
B21: Kwalifikowalne | C21: 0 | D21: 34550.27 | E21: 37200 | F21: 92.88 | G21: =IF(E21=0,0,D21/E21*100) -> 92.87707 | H21: =ROUND(G21-F21,2) -> 0
B22: Dofinansowanie | C22: 0 | D22: 27640.23 | E22: 29760 | F22: 92.88 | G22: =IF(E22=0,0,D22/E22*100) -> 92.877117 | H22: =ROUND(G22-F22,2) -> 0
A23: 1.6 Personel projektu - Grafik-Ilustrator | B23: Ogółem | C23: 0 | D23: 24600 | E23: 67325 | F23: 36.54 | G23: =IF(E23=0,0,D23/E23*100) -> 36.539176 | H23: =ROUND(G23-F23,2) -> 0
B24: Kwalifikowalne | C24: 0 | D24: 24600 | E24: 67325 | F24: 36.54 | G24: =IF(E24=0,0,D24/E24*100) -> 36.539176 | H24: =ROUND(G24-F24,2) -> 0
B25: Dofinansowanie | C25: 0 | D25: 19680 | E25: 53860 | F25: 36.54 | G25: =IF(E25=0,0,D25/E25*100) -> 36.539176 | H25: =ROUND(G25-F25,2) -> 0
A26: 1.7 Personel projektu - Analityk danych | B26: Ogółem | C26: 0 | D26: 103125 | E26: 103125 | F26: 100 | G26: =IF(E26=0,0,D26/E26*100) -> 100 | H26: =ROUND(G26-F26,2) -> 0
B27: Kwalifikowalne | C27: 0 | D27: 103125 | E27: 103125 | F27: 100 | G27: =IF(E27=0,0,D27/E27*100) -> 100 | H27: =ROUND(G27-F27,2) -> 0
B28: Dofinansowanie | C28: 0 | D28: 82500 | E28: 82500 | F28: 100 | G28: =IF(E28=0,0,D28/E28*100) -> 100 | H28: =ROUND(G28-F28,2) -> 0
A29: 1.8 Amortyzacja - Laptopy dla inżynierów AI | B29: Ogółem | C29: 0 | D29: 2276.08 | E29: 3571.43 | F29: 63.73 | G29: =IF(E29=0,0,D29/E29*100) -> 63.730215 | H29: =ROUND(G29-F29,2) -> 0
B30: Kwalifikowalne | C30: 0 | D30: 2276.08 | E30: 3571.43 | F30: 63.73 | G30: =IF(E30=0,0,D30/E30*100) -> 63.730215 | H30: =ROUND(G30-F30,2) -> 0
B31: Dofinansowanie | C31: 0 | D31: 1820.86 | E31: 2857.14 | F31: 63.73 | G31: =IF(E31=0,0,D31/E31*100) -> 63.730164 | H31: =ROUND(G31-F31,2) -> 0
A32: 1.9 Personel projektu - Architekt rozwiązań chmurowych | B32: Ogółem | C32: 0 | D32: 98750 | E32: 98750 | F32: 100 | G32: =IF(E32=0,0,D32/E32*100) -> 100 | H32: =ROUND(G32-F32,2) -> 0
B33: Kwalifikowalne | C33: 0 | D33: 98750 | E33: 98750 | F33: 100 | G33: =IF(E33=0,0,D33/E33*100) -> 100 | H33: =ROUND(G33-F33,2) -> 0
B34: Dofinansowanie | C34: 0 | D34: 79000 | E34: 79000 | F34: 100 | G34: =IF(E34=0,0,D34/E34*100) -> 100 | H34: =ROUND(G34-F34,2) -> 0
A35: Zadanie 2. Opracowanie i przebadanie prototypowej wersji metody - B + R | B35: Ogółem | C35: 335904.98 | D35: 1008769.3 | E35: 1226935.7 | F35: 82.22 | G35: =IF(E35=0,0,D35/E35*100) -> 82.218594 | H35: =ROUND(G35-F35,2) -> 0
B36: Kwalifikowalne | C36: 335904.98 | D36: 842569.29 | E36: 1203935.7 | F36: 69.98 | G36: =IF(E36=0,0,D36/E36*100) -> 69.984575 | H36: =ROUND(G36-F36,2) -> 0
B37: Dofinansowanie | C37: 268723.98 | D37: 674055.43 | E37: 963148.56 | F37: 69.98 | G37: =IF(E37=0,0,D37/E37*100) -> 69.984575 | H37: =ROUND(G37-F37,2) -> 0
A38: 2.1 Personel projektu - Ekspert AI | B38: Ogółem | C38: 110800 | D38: 332400 | E38: 332400 | F38: 100 | G38: =IF(E38=0,0,D38/E38*100) -> 100 | H38: =ROUND(G38-F38,2) -> 0
B39: Kwalifikowalne | C39: 110800 | D39: 166200 | E39: 332400 | F39: 50 | G39: =IF(E39=0,0,D39/E39*100) -> 50 | H39: =ROUND(G39-F39,2) -> 0
B40: Dofinansowanie | C40: 88640 | D40: 132960 | E40: 265920 | F40: 50 | G40: =IF(E40=0,0,D40/E40*100) -> 50 | H40: =ROUND(G40-F40,2) -> 0
A41: 2.2 Personel projektu - Big Data Engineer | B41: Ogółem | C41: 37720 | D41: 113168.16 | E41: 113160 | F41: 100.01 | G41: =IF(E41=0,0,D41/E41*100) -> 100.00721 | H41: =ROUND(G41-F41,2) -> 0
...

Sheet Kontrola
A1: Kontrola arytmetyczna (formuły) – tolerancja 0,02 zł
A2: Kontrola | B2: Rodzaj | C2: Kolumna | D2: Wartość z PDF | E2: Wyliczone z pozycji | F2: Różnica | G2: Status
A3: Zadanie 1 = suma pozycji 1.x | B3: Ogółem | C3: bieżące | D3: =Podsumowanie!C5 -> 0 | E3: =Podsumowanie!C8+Podsumowanie!C11+Podsumowanie!C14+Podsumowanie!C17+Podsumowanie!C20+Podsumowanie!C23+Podsumowanie!C26+Podsumowanie!C29+Podsumowanie!C32 -> 0 | F3: =ROUND(D3-E3,2) -> 0 | G3: =IF(ABS(F3)<=0.02,"OK","BŁĄD") -> OK
A4: Zadanie 1 = suma pozycji 1.x | B4: Ogółem | C4: narastająco | D4: =Podsumowanie!D5 -> 807424.87 | E4: =Podsumowanie!D8+Podsumowanie!D11+Podsumowanie!D14+Podsumowanie!D17+Podsumowanie!D20+Podsumowanie!D23+Podsumowanie!D26+Podsumowanie!D29+Podsumowanie!D32 -> 807424.87 | F4: =ROUND(D4-E4,2) -> 0 | G4: =IF(ABS(F4)<=0.02,"OK","BŁĄD") -> OK
A5: Zadanie 1 = suma pozycji 1.x | B5: Ogółem | C5: w projekcie | D5: =Podsumowanie!E5 -> 868383.93 | E5: =Podsumowanie!E8+Podsumowanie!E11+Podsumowanie!E14+Podsumowanie!E17+Podsumowanie!E20+Podsumowanie!E23+Podsumowanie!E26+Podsumowanie!E29+Podsumowanie!E32 -> 868383.93 | F5: =ROUND(D5-E5,2) -> 0 | G5: =IF(ABS(F5)<=0.02,"OK","BŁĄD") -> OK
A6: Zadanie 1 = suma pozycji 1.x | B6: Kwalifikowalne | C6: bieżące | D6: =Podsumowanie!C6 -> 0 | E6: =Podsumowanie!C9+Podsumowanie!C12+Podsumowanie!C15+Podsumowanie!C18+Podsumowanie!C21+Podsumowanie!C24+Podsumowanie!C27+Podsumowanie!C30+Podsumowanie!C33 -> 0 | F6: =ROUND(D6-E6,2) -> 0 | G6: =IF(ABS(F6)<=0.02,"OK","BŁĄD") -> OK
A7: Zadanie 1 = suma pozycji 1.x | B7: Kwalifikowalne | C7: narastająco | D7: =Podsumowanie!D6 -> 807424.87 | E7: =Podsumowanie!D9+Podsumowanie!D12+Podsumowanie!D15+Podsumowanie!D18+Podsumowanie!D21+Podsumowanie!D24+Podsumowanie!D27+Podsumowanie!D30+Podsumowanie!D33 -> 807424.87 | F7: =ROUND(D7-E7,2) -> 0 | G7: =IF(ABS(F7)<=0.02,"OK","BŁĄD") -> OK
A8: Zadanie 1 = suma pozycji 1.x | B8: Kwalifikowalne | C8: w projekcie | D8: =Podsumowanie!E6 -> 868383.93 | E8: =Podsumowanie!E9+Podsumowanie!E12+Podsumowanie!E15+Podsumowanie!E18+Podsumowanie!E21+Podsumowanie!E24+Podsumowanie!E27+Podsumowanie!E30+Podsumowanie!E33 -> 868383.93 | F8: =ROUND(D8-E8,2) -> 0 | G8: =IF(ABS(F8)<=0.02,"OK","BŁĄD") -> OK
A9: Zadanie 1 = suma pozycji 1.x | B9: Dofinansowanie | C9: bieżące | D9: =Podsumowanie!C7 -> 0 | E9: =Podsumowanie!C10+Podsumowanie!C13+Podsumowanie!C16+Podsumowanie!C19+Podsumowanie!C22+Podsumowanie!C25+Podsumowanie!C28+Podsumowanie!C31+Podsumowanie!C34 -> 0 | F9: =ROUND(D9-E9,2) -> 0 | G9: =IF(ABS(F9)<=0.02,"OK","BŁĄD") -> OK
A10: Zadanie 1 = suma pozycji 1.x | B10: Dofinansowanie | C10: narastająco | D10: =Podsumowanie!D7 -> 645939.9 | E10: =Podsumowanie!D10+Podsumowanie!D13+Podsumowanie!D16+Podsumowanie!D19+Podsumowanie!D22+Podsumowanie!D25+Podsumowanie!D28+Podsumowanie!D31+Podsumowanie!D34 -> 645939.9 | F10: =ROUND(D10-E10,2) -> 0 | G10: =IF(ABS(F10)<=0.02,"OK","BŁĄD") -> OK
A11: Zadanie 1 = suma pozycji 1.x | B11: Dofinansowanie | C11: w projekcie | D11: =Podsumowanie!E7 -> 694707.14 | E11: =Podsumowanie!E10+Podsumowanie!E13+Podsumowanie!E16+Podsumowanie!E19+Podsumowanie!E22+Podsumowanie!E25+Podsumowanie!E28+Podsumowanie!E31+Podsumowanie!E34 -> 694707.14 | F11: =ROUND(D11-E11,2) -> 0 | G11: =IF(ABS(F11)<=0.02,"OK","BŁĄD") -> OK
A12: Zadanie 2 = suma pozycji 2.x | B12: Ogółem | C12: bieżące | D12: =Podsumowanie!C35 -> 335904.98 | E12: =Podsumowanie!C38+Podsumowanie!C41+Podsumowanie!C44+Podsumowanie!C47+Podsumowanie!C50+Podsumowanie!C53+Podsumowanie!C56+Podsumowanie!C59+Podsumowanie!C62+Podsumowanie!C65 -> 335904.98 | F12: =ROUND(D12-E12,2) -> 0 | G12: =IF(ABS(F12)<=0.02,"OK","BŁĄD") -> OK
A13: Zadanie 2 = suma pozycji 2.x | B13: Ogółem | C13: narastająco | D13: =Podsumowanie!D35 -> 1008769.3 | E13: =Podsumowanie!D38+Podsumowanie!D41+Podsumowanie!D44+Podsumowanie!D47+Podsumowanie!D50+Podsumowanie!D53+Podsumowanie!D56+Podsumowanie!D59+Podsumowanie!D62+Podsumowanie!D65 -> 1008769.3 | F13: =ROUND(D13-E13,2) -> 0 | G13: =IF(ABS(F13)<=0.02,"OK","BŁĄD") -> OK
A14: Zadanie 2 = suma pozycji 2.x | B14: Ogółem | C14: w projekcie | D14: =Podsumowanie!E35 -> 1226935.7 | E14: =Podsumowanie!E38+Podsumowanie!E41+Podsumowanie!E44+Podsumowanie!E47+Podsumowanie!E50+Podsumowanie!E53+Podsumowanie!E56+Podsumowanie!E59+Podsumowanie!E62+Podsumowanie!E65 -> 1226935.7 | F14: =ROUND(D14-E14,2) -> 0 | G14: =IF(ABS(F14)<=0.02,"OK","BŁĄD") -> OK
A15: Zadanie 2 = suma pozycji 2.x | B15: Kwalifikowalne | C15: bieżące | D15: =Podsumowanie!C36 -> 335904.98 | E15: =Podsumowanie!C39+Podsumowanie!C42+Podsumowanie!C45+Podsumowanie!C48+Podsumowanie!C51+Podsumowanie!C54+Podsumowanie!C57+Podsumowanie!C60+Podsumowanie!C63+Podsumowanie!C66 -> 335904.98 | F15: =ROUND(D15-E15,2) -> 0 | G15: =IF(ABS(F15)<=0.02,"OK","BŁĄD") -> OK
A16: Zadanie 2 = suma pozycji 2.x | B16: Kwalifikowalne | C16: narastająco | D16: =Podsumowanie!D36 -> 842569.29 | E16: =Podsumowanie!D39+Podsumowanie!D42+Podsumowanie!D45+Podsumowanie!D48+Podsumowanie!D51+Podsumowanie!D54+Podsumowanie!D57+Podsumowanie!D60+Podsumowanie!D63+Podsumowanie!D66 -> 842569.29 | F16: =ROUND(D16-E16,2) -> 0 | G16: =IF(ABS(F16)<=0.02,"OK","BŁĄD") -> OK
A17: Zadanie 2 = suma pozycji 2.x | B17: Kwalifikowalne | C17: w projekcie | D17: =Podsumowanie!E36 -> 1203935.7 | E17: =Podsumowanie!E39+Podsumowanie!E42+Podsumowanie!E45+Podsumowanie!E48+Podsumowanie!E51+Podsumowanie!E54+Podsumowanie!E57+Podsumowanie!E60+Podsumowanie!E63+Podsumowanie!E66 -> 1203935.7 | F17: =ROUND(D17-E17,2) -> 0 | G17: =IF(ABS(F17)<=0.02,"OK","BŁĄD") -> OK
A18: Zadanie 2 = suma pozycji 2.x | B18: Dofinansowanie | C18: bieżące | D18: =Podsumowanie!C37 -> 268723.98 | E18: =Podsumowanie!C40+Podsumowanie!C43+Podsumowanie!C46+Podsumowanie!C49+Podsumowanie!C52+Podsumowanie!C55+Podsumowanie!C58+Podsumowanie!C61+Podsumowanie!C64+Podsumowanie!C67 -> 268723.98 | F18: =ROUND(D18-E18,2) -> 0 | G18: =IF(ABS(F18)<=0.02,"OK","BŁĄD") -> OK
A19: Zadanie 2 = suma pozycji 2.x | B19: Dofinansowanie | C19: narastająco | D19: =Podsumowanie!D37 -> 674055.43 | E19: =Podsumowanie!D40+Podsumowanie!D43+Podsumowanie!D46+Podsumowanie!D49+Podsumowanie!D52+Podsumowanie!D55+Podsumowanie!D58+Podsumowanie!D61+Podsumowanie!D64+Podsumowanie!D67 -> 674055.43 | F19: =ROUND(D19-E19,2) -> 0 | G19: =IF(ABS(F19)<=0.02,"OK","BŁĄD") -> OK
A20: Zadanie 2 = suma pozycji 2.x | B20: Dofinansowanie | C20: w projekcie | D20: =Podsumowanie!E37 -> 963148.56 | E20: =Podsumowanie!E40+Podsumowanie!E43+Podsumowanie!E46+Podsumowanie!E49+Podsumowanie!E52+Podsumowanie!E55+Podsumowanie!E58+Podsumowanie!E61+Podsumowanie!E64+Podsumowanie!E67 -> 963148.56 | F20: =ROUND(D20-E20,2) -> 0 | G20: =IF(ABS(F20)<=0.02,"OK","BŁĄD") -> OK
A21: Zadanie 3 = suma pozycji 3.x | B21: Ogółem | C21: bieżące | D21: =Podsumowanie!C68 -> 0 | E21: =Podsumowanie!C71+Podsumowanie!C74+Podsumowanie!C77+Podsumowanie!C80+Podsumowanie!C83+Podsumowanie!C86+Podsumowanie!C89+Podsumowanie!C92+Podsumowanie!C95 -> 0 | F21: =ROUND(D21-E21,2) -> 0 | G21: =IF(ABS(F21)<=0.02,"OK","BŁĄD") -> OK
A22: Zadanie 3 = suma pozycji 3.x | B22: Ogółem | C22: narastająco | D22: =Podsumowanie!D68 -> 0 | E22: =Podsumowanie!D71+Podsumowanie!D74+Podsumowanie!D77+Podsumowanie!D80+Podsumowanie!D83+Podsumowanie!D86+Podsumowanie!D89+Podsumowanie!D92+Podsumowanie!D95 -> 0 | F22: =ROUND(D22-E22,2) -> 0 | G22: =IF(ABS(F22)<=0.02,"OK","BŁĄD") -> OK
A23: Zadanie 3 = suma pozycji 3.x | B23: Ogółem | C23: w projekcie | D23: =Podsumowanie!E68 -> 1103935.7 | E23: =Podsumowanie!E71+Podsumowanie!E74+Podsumowanie!E77+Podsumowanie!E80+Podsumowanie!E83+Podsumowanie!E86+Podsumowanie!E89+Podsumowanie!E92+Podsumowanie!E95 -> 1103935.7 | F23: =ROUND(D23-E23,2) -> 0 | G23: =IF(ABS(F23)<=0.02,"OK","BŁĄD") -> OK
A24: Zadanie 3 = suma pozycji 3.x | B24: Kwalifikowalne | C24: bieżące | D24: =Podsumowanie!C69 -> 0 | E24: =Podsumowanie!C72+Podsumowanie!C75+Podsumowanie!C78+Podsumowanie!C81+Podsumowanie!C84+Podsumowanie!C87+Podsumowanie!C90+Podsumowanie!C93+Podsumowanie!C96 -> 0 | F24: =ROUND(D24-E24,2) -> 0 | G24: =IF(ABS(F24)<=0.02,"OK","BŁĄD") -> OK
A25: Zadanie 3 = suma pozycji 3.x | B25: Kwalifikowalne | C25: narastająco | D25: =Podsumowanie!D69 -> 0 | E25: =Podsumowanie!D72+Podsumowanie!D75+Podsumowanie!D78+Podsumowanie!D81+Podsumowanie!D84+Podsumowanie!D87+Podsumowanie!D90+Podsumowanie!D93+Podsumowanie!D96 -> 0 | F25: =ROUND(D25-E25,2) -> 0 | G25: =IF(ABS(F25)<=0.02,"OK","BŁĄD") -> OK
A26: Zadanie 3 = suma pozycji 3.x | B26: Kwalifikowalne | C26: w projekcie | D26: =Podsumowanie!E69 -> 1103935.7 | E26: =Podsumowanie!E72+Podsumowanie!E75+Podsumowanie!E78+Podsumowanie!E81+Podsumowanie!E84+Podsumowanie!E87+Podsumowanie!E90+Podsumowanie!E93+Podsumowanie!E96 -> 1103935.7 | F26: =ROUND(D26-E26,2) -> 0 | G26: =IF(ABS(F26)<=0.02,"OK","BŁĄD") -> OK
A27: Zadanie 3 = suma pozycji 3.x | B27: Dofinansowanie | C27: bieżące | D27: =Podsumowanie!C70 -> 0 | E27: =Podsumowanie!C73+Podsumowanie!C76+Podsumowanie!C79+Podsumowanie!C82+Podsumowanie!C85+Podsumowanie!C88+Podsumowanie!C91+Podsumowanie!C94+Podsumowanie!C97 -> 0 | F27: =ROUND(D27-E27,2) -> 0 | G27: =IF(ABS(F27)<=0.02,"OK","BŁĄD") -> OK
A28: Zadanie 3 = suma pozycji 3.x | B28: Dofinansowanie | C28: narastająco | D28: =Podsumowanie!D70 -> 0 | E28: =Podsumowanie!D73+Podsumowanie!D76+Podsumowanie!D79+Podsumowanie!D82+Podsumowanie!D85+Podsumowanie!D88+Podsumowanie!D91+Podsumowanie!D94+Podsumowanie!D97 -> 0 | F28: =ROUND(D28-E28,2) -> 0 | G28: =IF(ABS(F28)<=0.02,"OK","BŁĄD") -> OK
A29: Zadanie 3 = suma pozycji 3.x | B29: Dofinansowanie | C29: w projekcie | D29: =Podsumowanie!E70 -> 883148.56 | E29: =Podsumowanie!E73+Podsumowanie!E76+Podsumowanie!E79+Podsumowanie!E82+Podsumowanie!E85+Podsumowanie!E88+Podsumowanie!E91+Podsumowanie!E94+Podsumowanie!E97 -> 883148.56 | F29: =ROUND(D29-E29,2) -> 0 | G29: =IF(ABS(F29)<=0.02,"OK","BŁĄD") -> OK
A30: Zadanie 4 = suma pozycji 4.x | B30: Ogółem | C30: bieżące | D30: =Podsumowanie!C98 -> 0 | E30: =Podsumowanie!C101+Podsumowanie!C104+Podsumowanie!C107+Podsumowanie!C110+Podsumowanie!C113+Podsumowanie!C116+Podsumowanie!C119+Podsumowanie!C122+Podsumowanie!C125 -> 0 | F30: =ROUND(D30-E30,2) -> 0 | G30: =IF(ABS(F30)<=0.02,"OK","BŁĄD") -> OK
A31: Zadanie 4 = suma pozycji 4.x | B31: Ogółem | C31: narastająco | D31: =Podsumowanie!D98 -> 0 | E31: =Podsumowanie!D101+Podsumowanie!D104+Podsumowanie!D107+Podsumowanie!D110+Podsumowanie!D113+Podsumowanie!D116+Podsumowanie!D119+Podsumowanie!D122+Podsumowanie!D125 -> 0 | F31: =ROUND(D31-E31,2) -> 0 | G31: =IF(ABS(F31)<=0.02,"OK","BŁĄD") -> OK
A32: Zadanie 4 = suma pozycji 4.x | B32: Ogółem | C32: w projekcie | D32: =Podsumowanie!E98 -> 698237.14 | E32: =Podsumowanie!E101+Podsumowanie!E104+Podsumowanie!E107+Podsumowanie!E110+Podsumowanie!E113+Podsumowanie!E116+Podsumowanie!E119+Podsumowanie!E122+Podsumowanie!E125 -> 698237.14 | F32: =ROUND(D32-E32,2) -> 0 | G32: =IF(ABS(F32)<=0.02,"OK","BŁĄD") -> OK
A33: Zadanie 4 = suma pozycji 4.x | B33: Kwalifikowalne | C33: bieżące | D33: =Podsumowanie!C99 -> 0 | E33: =Podsumowanie!C102+Podsumowanie!C105+Podsumowanie!C108+Podsumowanie!C111+Podsumowanie!C114+Podsumowanie!C117+Podsumowanie!C120+Podsumowanie!C123+Podsumowanie!C126 -> 0 | F33: =ROUND(D33-E33,2) -> 0 | G33: =IF(ABS(F33)<=0.02,"OK","BŁĄD") -> OK
A34: Zadanie 4 = suma pozycji 4.x | B34: Kwalifikowalne | C34: narastająco | D34: =Podsumowanie!D99 -> 0 | E34: =Podsumowanie!D102+Podsumowanie!D105+Podsumowanie!D108+Podsumowanie!D111+Podsumowanie!D114+Podsumowanie!D117+Podsumowanie!D120+Podsumowanie!D123+Podsumowanie!D126 -> 0 | F34: =ROUND(D34-E34,2) -> 0 | G34: =IF(ABS(F34)<=0.02,"OK","BŁĄD") -> OK
A35: Zadanie 4 = suma pozycji 4.x | B35: Kwalifikowalne | C35: w projekcie | D35: =Podsumowanie!E99 -> 698237.14 | E35: =Podsumowanie!E102+Podsumowanie!E105+Podsumowanie!E108+Podsumowanie!E111+Podsumowanie!E114+Podsumowanie!E117+Podsumowanie!E120+Podsumowanie!E123+Podsumowanie!E126 -> 698237.14 | F35: =ROUND(D35-E35,2) -> 0 | G35: =IF(ABS(F35)<=0.02,"OK","BŁĄD") -> OK
A36: Zadanie 4 = suma pozycji 4.x | B36: Dofinansowanie | C36: bieżące | D36: =Podsumowanie!C100 -> 0 | E36: =Podsumowanie!C103+Podsumowanie!C106+Podsumowanie!C109+Podsumowanie!C112+Podsumowanie!C115+Podsumowanie!C118+Podsumowanie!C121+Podsumowanie!C124+Podsumowanie!C127 -> 0 | F36: =ROUND(D36-E36,2) -> 0 | G36: =IF(ABS(F36)<=0.02,"OK","BŁĄD") -> OK
A37: Zadanie 4 = suma pozycji 4.x | B37: Dofinansowanie | C37: narastająco | D37: =Podsumowanie!D100 -> 0 | E37: =Podsumowanie!D103+Podsumowanie!D106+Podsumowanie!D109+Podsumowanie!D112+Podsumowanie!D115+Podsumowanie!D118+Podsumowanie!D121+Podsumowanie!D124+Podsumowanie!D127 -> 0 | F37: =ROUND(D37-E37,2) -> 0 | G37: =IF(ABS(F37)<=0.02,"OK","BŁĄD") -> OK
A38: Zadanie 4 = suma pozycji 4.x | B38: Dofinansowanie | C38: w projekcie | D38: =Podsumowanie!E100 -> 418942.28 | E38: =Podsumowanie!E103+Podsumowanie!E106+Podsumowanie!E109+Podsumowanie!E112+Podsumowanie!E115+Podsumowanie!E118+Podsumowanie!E121+Podsumowanie!E124+Podsumowanie!E127 -> 418942.28 | F38: =ROUND(D38-E38,2) -> 0 | G38: =IF(ABS(F38)<=0.02,"OK","BŁĄD") -> OK
A39: Koszty bezpośrednie = suma zadań | B39: Ogółem | C39: bieżące | D39: =Podsumowanie!C145 -> 335904.98 | E39: =Podsumowanie!C5+Podsumowanie!C35+Podsumowanie!C68+Podsumowanie!C98 -> 335904.98 | F39: =ROUND(D39-E39,2) -> 0 | G39: =IF(ABS(F39)<=0.02,"OK","BŁĄD") -> OK
A40: Razem = bezpośrednie + pośrednie | B40: Ogółem | C40: bieżące | D40: =Podsumowanie!C136 -> 335904.98 | E40: =Podsumowanie!C145+Podsumowanie!C130 -> 335904.98 | F40: =ROUND(D40-E40,2) -> 0 | G40: =IF(ABS(F40)<=0.02,"OK","BŁĄD") -> OK
...

Sheet Uwagi
A1: Uwaga | B1: Opis
A2: Wynik kontroli | B2: Wszystkie sumy (zadania, koszty bezpośrednie, razem, kategorie) zgadzają się co do grosza – patrz arkusz Kontrola.
A3: Zadanie 4 – intensywność dofinansowania | B3: W Zadaniu 4 (poz. 4.1–4.9) dofinansowanie wynosi 60% kwoty kwalifikowalnej w projekcie (np. 4.1: 132 960 / 221 600), w Zadaniach 1–3 jest to 80%. Zweryfikować, czy to zamierzone (np. inna intensywność pomocy) – wpływa na łączne dofinansowanie 3 699 933,17.
A4: Poz. 2.2 – przekroczenie | B4: Narastająco 113 168,16 > w projekcie 113 160,00 (100,01%); dofinansowanie 90 534,53 > 90 528,00. Przekroczenie o 8,16 zł (6,53 zł dofin.). Do wyjaśnienia / korekty.
A5: Poz. 2.1 – kwalifikowalne narastająco | B5: Ogółem narastająco 332 400,00, kwalifikowalne tylko 166 200,00 (50%), podczas gdy w projekcie kwalifikowalne = ogółem (332 400,00). Sprawdzić, czy część wydatków nie została celowo uznana za niekwalifikowalną.
A6: Poz. 1.8 vs 2.9 – zaokrąglenie | B6: Ta sama kwota kwalifikowalna 2 276,08, dofinansowanie 1 820,86 (1.8) vs 1 820,88 (2.9) – różnica 0,02 zł, zaokrąglenia. Suma 3 641,74 zgodna z kategorią Amortyzacja.
A7: Koszty pośrednie | B7: Ryczałt 25%: w projekcie 968 623,12 = 25% × 3 874 492,49 (OK). Narastająco 328 522,30 = 25% × (1 649 994,16 – 335 904,98), tj. liczone bez wydatków bieżącego wniosku – spójne, wydatki pośrednie za bieżący okres = 0,00.
A8: Str. 26 – polityki wspólnotowe | B8: Oświadczenie: 'Projekt jest realizowany zgodnie z zasadami polityk wspólnotowych: Nie', a opis nieprawidłowości/działań naprawczych: 'Brak danych'. Wygląda na niewypełnione/błędne pole – jeśli projekt jest zgodny, powinno być 'Tak'; jeśli nie, wymagany jest opis.
A9: Str. 26 – dokument roboczy | B9: Dokument ma znak wodny 'WERSJA ROBOCZA'; pole 'Numer wniosku' puste.
A10: Zadania 3–4 | B10: Wydatki bieżące i narastająco = 0,00 (jeszcze niezrealizowane) – prawidłowo.
A11: Nazwy | B11: W nazwach zadań usunięto zdublowaną numerację (PDF: 'Zadanie 1. 1. …').

Sheet nowy format
B1: wydatki narastająco | E1: wydatki w projekcie
A2: Pozycja budżetowa | B2: wydatki ogółem | C2: wydatki kwalifikowane | D2: dofinansowanie | E2: wydatki ogółem | F2: wydatki kwalifikowane | G2: dofinansowanie
A3: Zadanie 1. Opracowanie narzędzi i przeprowadzenie badań w celu parametryzacji obrazów - B + R | B3: =Podsumowanie!D5 -> 807424.87 | C3: =Podsumowanie!D6 -> 807424.87 | D3: =Podsumowanie!D7 -> 645939.9 | E3: =Podsumowanie!E5 -> 868383.93 | F3: =Podsumowanie!E6 -> 868383.93 | G3: =Podsumowanie!E7 -> 694707.14
A4: 1.1 Personel projektu - Ekspert AI | B4: =Podsumowanie!D8 -> 277000 | C4: =Podsumowanie!D9 -> 277000 | D4: =Podsumowanie!D10 -> 221600 | E4: =Podsumowanie!E8 -> 277000 | F4: =Podsumowanie!E9 -> 277000 | G4: =Podsumowanie!E10 -> 221600
A5: 1.2 Personel projektu - Big Data Engineer | B5: =Podsumowanie!D11 -> 94300 | C5: =Podsumowanie!D12 -> 94300 | D5: =Podsumowanie!D13 -> 75440 | E5: =Podsumowanie!E11 -> 94300 | F5: =Podsumowanie!E12 -> 94300 | G5: =Podsumowanie!E13 -> 75440
A6: 1.3 Personel projektu - Ekspert ds. psychometrii | B6: =Podsumowanie!D14 -> 121994.98 | C6: =Podsumowanie!D15 -> 121994.98 | D6: =Podsumowanie!D16 -> 97595.98 | E6: =Podsumowanie!E14 -> 135550 | F6: =Podsumowanie!E15 -> 135550 | G6: =Podsumowanie!E16 -> 108440
A7: 1.4 Personel projektu - Senior Developer | B7: =Podsumowanie!D17 -> 50828.54 | C7: =Podsumowanie!D18 -> 50828.54 | D7: =Podsumowanie!D19 -> 40662.83 | E7: =Podsumowanie!E17 -> 51562.5 | F7: =Podsumowanie!E18 -> 51562.5 | G7: =Podsumowanie!E19 -> 41250
A8: 1.5 Personel projektu - Automation QA Engineer | B8: =Podsumowanie!D20 -> 34550.27 | C8: =Podsumowanie!D21 -> 34550.27 | D8: =Podsumowanie!D22 -> 27640.23 | E8: =Podsumowanie!E20 -> 37200 | F8: =Podsumowanie!E21 -> 37200 | G8: =Podsumowanie!E22 -> 29760
A9: 1.6 Personel projektu - Grafik-Ilustrator | B9: =Podsumowanie!D23 -> 24600 | C9: =Podsumowanie!D24 -> 24600 | D9: =Podsumowanie!D25 -> 19680 | E9: =Podsumowanie!E23 -> 67325 | F9: =Podsumowanie!E24 -> 67325 | G9: =Podsumowanie!E25 -> 53860
A10: 1.7 Personel projektu - Analityk danych | B10: =Podsumowanie!D26 -> 103125 | C10: =Podsumowanie!D27 -> 103125 | D10: =Podsumowanie!D28 -> 82500 | E10: =Podsumowanie!E26 -> 103125 | F10: =Podsumowanie!E27 -> 103125 | G10: =Podsumowanie!E28 -> 82500
A11: 1.8 Amortyzacja - Laptopy dla inżynierów AI | B11: =Podsumowanie!D29 -> 2276.08 | C11: =Podsumowanie!D30 -> 2276.08 | D11: =Podsumowanie!D31 -> 1820.86 | E11: =Podsumowanie!E29 -> 3571.43 | F11: =Podsumowanie!E30 -> 3571.43 | G11: =Podsumowanie!E31 -> 2857.14
A12: 1.9 Personel projektu - Architekt rozwiązań chmurowych | B12: =Podsumowanie!D32 -> 98750 | C12: =Podsumowanie!D33 -> 98750 | D12: =Podsumowanie!D34 -> 79000 | E12: =Podsumowanie!E32 -> 98750 | F12: =Podsumowanie!E33 -> 98750 | G12: =Podsumowanie!E34 -> 79000
A13: Zadanie 2. Opracowanie i przebadanie prototypowej wersji metody - B + R | B13: =Podsumowanie!D35 -> 1008769.3 | C13: =Podsumowanie!D36 -> 842569.29 | D13: =Podsumowanie!D37 -> 674055.43 | E13: =Podsumowanie!E35 -> 1226935.7 | F13: =Podsumowanie!E36 -> 1203935.7 | G13: =Podsumowanie!E37 -> 963148.56
A14: 2.1 Personel projektu - Ekspert AI | B14: =Podsumowanie!D38 -> 332400 | C14: =Podsumowanie!D39 -> 166200 | D14: =Podsumowanie!D40 -> 132960 | E14: =Podsumowanie!E38 -> 332400 | F14: =Podsumowanie!E39 -> 332400 | G14: =Podsumowanie!E40 -> 265920
A15: 2.2 Personel projektu - Big Data Engineer | B15: =Podsumowanie!D41 -> 113168.16 | C15: =Podsumowanie!D42 -> 113168.16 | D15: =Podsumowanie!D43 -> 90534.53 | E15: =Podsumowanie!E41 -> 113160 | F15: =Podsumowanie!E42 -> 113160 | G15: =Podsumowanie!E43 -> 90528
A16: 2.3 Personel projektu - Ekspert ds. psychometrii | B16: =Podsumowanie!D44 -> 121024.78 | C16: =Podsumowanie!D45 -> 121024.78 | D16: =Podsumowanie!D46 -> 96819.8 | E16: =Podsumowanie!E44 -> 162660 | F16: =Podsumowanie!E45 -> 162660 | G16: =Podsumowanie!E46 -> 130128
A17: 2.4 Personel projektu - Senior Developer | B17: =Podsumowanie!D47 -> 123750 | C17: =Podsumowanie!D48 -> 123750 | D17: =Podsumowanie!D49 -> 99000 | E17: =Podsumowanie!E47 -> 123750 | F17: =Podsumowanie!E48 -> 123750 | G17: =Podsumowanie!E49 -> 99000
A18: 2.5 Personel projektu - Automation QA Engineer | B18: =Podsumowanie!D50 -> 44388.77 | C18: =Podsumowanie!D51 -> 44388.77 | D18: =Podsumowanie!D52 -> 35511.02 | E18: =Podsumowanie!E50 -> 44640 | F18: =Podsumowanie!E51 -> 44640 | G18: =Podsumowanie!E52 -> 35712
A19: 2.6 Personel projektu - Analityk danych | B19: =Podsumowanie!D53 -> 123750 | C19: =Podsumowanie!D54 -> 123750 | D19: =Podsumowanie!D55 -> 99000 | E19: =Podsumowanie!E53 -> 123750 | F19: =Podsumowanie!E54 -> 123750 | G19: =Podsumowanie!E55 -> 99000
A20: 2.7 Personel projektu - Grafik-Ilustrator | B20: =Podsumowanie!D56 -> 29517.79 | C20: =Podsumowanie!D57 -> 29517.79 | D20: =Podsumowanie!D58 -> 23614.23 | E20: =Podsumowanie!E56 -> 80790 | F20: =Podsumowanie!E57 -> 80790 | G20: =Podsumowanie!E58 -> 64632
A21: 2.8 Wartości niematerialne i prawne - Licencje psychometrycznego narzędzia referencyjnego | B21: =Podsumowanie!D59 -> 0 | C21: =Podsumowanie!D60 -> 0 | D21: =Podsumowanie!D61 -> 0 | E21: =Podsumowanie!E59 -> 123000 | F21: =Podsumowanie!E60 -> 100000 | G21: =Podsumowanie!E61 -> 80000
A22: 2.9 Amortyzacja - Laptopy dla inżynierów AI | B22: =Podsumowanie!D62 -> 2276.08 | C22: =Podsumowanie!D63 -> 2276.08 | D22: =Podsumowanie!D64 -> 1820.88 | E22: =Podsumowanie!E62 -> 4285.71 | F22: =Podsumowanie!E63 -> 4285.71 | G22: =Podsumowanie!E64 -> 3428.56
A23: 2.10 Personel projektu - Architekt rozwiązań chmurowych | B23: =Podsumowanie!D65 -> 118493.71 | C23: =Podsumowanie!D66 -> 118493.71 | D23: =Podsumowanie!D67 -> 94794.97 | E23: =Podsumowanie!E65 -> 118500 | F23: =Podsumowanie!E66 -> 118500 | G23: =Podsumowanie!E67 -> 94800
A24: Zadanie 3. Opracowanie i weryfikacja reprezentatywnego modelu systemu - B + R | B24: =Podsumowanie!D68 -> 0 | C24: =Podsumowanie!D69 -> 0 | D24: =Podsumowanie!D70 -> 0 | E24: =Podsumowanie!E68 -> 1103935.7 | F24: =Podsumowanie!E69 -> 1103935.7 | G24: =Podsumowanie!E70 -> 883148.56
A25: 3.1 Personel projektu - Ekspert AI | B25: =Podsumowanie!D71 -> 0 | C25: =Podsumowanie!D72 -> 0 | D25: =Podsumowanie!D73 -> 0 | E25: =Podsumowanie!E71 -> 332400 | F25: =Podsumowanie!E72 -> 332400 | G25: =Podsumowanie!E73 -> 265920
A26: 3.2 Personel projektu - Big Data Engineer | B26: =Podsumowanie!D74 -> 0 | C26: =Podsumowanie!D75 -> 0 | D26: =Podsumowanie!D76 -> 0 | E26: =Podsumowanie!E74 -> 113160 | F26: =Podsumowanie!E75 -> 113160 | G26: =Podsumowanie!E76 -> 90528
A27: 3.3 Personel projektu - Ekspert ds. psychometrii | B27: =Podsumowanie!D77 -> 0 | C27: =Podsumowanie!D78 -> 0 | D27: =Podsumowanie!D79 -> 0 | E27: =Podsumowanie!E77 -> 162660 | F27: =Podsumowanie!E78 -> 162660 | G27: =Podsumowanie!E79 -> 130128
A28: 3.4 Personel projektu - Senior Developer | B28: =Podsumowanie!D80 -> 0 | C28: =Podsumowanie!D81 -> 0 | D28: =Podsumowanie!D82 -> 0 | E28: =Podsumowanie!E80 -> 123750 | F28: =Podsumowanie!E81 -> 123750 | G28: =Podsumowanie!E82 -> 99000
A29: 3.5 Personel projektu - Automation QA Engineer | B29: =Podsumowanie!D83 -> 0 | C29: =Podsumowanie!D84 -> 0 | D29: =Podsumowanie!D85 -> 0 | E29: =Podsumowanie!E83 -> 44640 | F29: =Podsumowanie!E84 -> 44640 | G29: =Podsumowanie!E85 -> 35712
A30: 3.6 Personel projektu - Analityk danych | B30: =Podsumowanie!D86 -> 0 | C30: =Podsumowanie!D87 -> 0 | D30: =Podsumowanie!D88 -> 0 | E30: =Podsumowanie!E86 -> 123750 | F30: =Podsumowanie!E87 -> 123750 | G30: =Podsumowanie!E88 -> 99000
A31: 3.7 Personel projektu - Grafik-Ilustrator | B31: =Podsumowanie!D89 -> 0 | C31: =Podsumowanie!D90 -> 0 | D31: =Podsumowanie!D91 -> 0 | E31: =Podsumowanie!E89 -> 80790 | F31: =Podsumowanie!E90 -> 80790 | G31: =Podsumowanie!E91 -> 64632
A32: 3.8 Amortyzacja - Laptopy dla inżynierów AI | B32: =Podsumowanie!D92 -> 0 | C32: =Podsumowanie!D93 -> 0 | D32: =Podsumowanie!D94 -> 0 | E32: =Podsumowanie!E92 -> 4285.71 | F32: =Podsumowanie!E93 -> 4285.71 | G32: =Podsumowanie!E94 -> 3428.56
A33: 3.9 Personel projektu - Architekt rozwiązań chmurowych | B33: =Podsumowanie!D95 -> 0 | C33: =Podsumowanie!D96 -> 0 | D33: =Podsumowanie!D97 -> 0 | E33: =Podsumowanie!E95 -> 118500 | F33: =Podsumowanie!E96 -> 118500 | G33: =Podsumowanie!E97 -> 94800
A34: Zadanie 4. Opracowanie i walidacja docelowej wersji systemu - B + R | B34: =Podsumowanie!D98 -> 0 | C34: =Podsumowanie!D99 -> 0 | D34: =Podsumowanie!D100 -> 0 | E34: =Podsumowanie!E98 -> 698237.14 | F34: =Podsumowanie!E99 -> 698237.14 | G34: =Podsumowanie!E100 -> 418942.28
A35: 4.1 Personel projektu - AI Engineer | B35: =Podsumowanie!D101 -> 0 | C35: =Podsumowanie!D102 -> 0 | D35: =Podsumowanie!D103 -> 0 | E35: =Podsumowanie!E101 -> 221600 | F35: =Podsumowanie!E102 -> 221600 | G35: =Podsumowanie!E103 -> 132960
A36: 4.2 Personel projektu - Big Data Engineer | B36: =Podsumowanie!D104 -> 0 | C36: =Podsumowanie!D105 -> 0 | D36: =Podsumowanie!D106 -> 0 | E36: =Podsumowanie!E104 -> 37720 | F36: =Podsumowanie!E105 -> 37720 | G36: =Podsumowanie!E106 -> 22632
A37: 4.3 Personel projektu - Ekspert ds. psychometrii | B37: =Podsumowanie!D107 -> 0 | C37: =Podsumowanie!D108 -> 0 | D37: =Podsumowanie!D109 -> 0 | E37: =Podsumowanie!E107 -> 108440 | F37: =Podsumowanie!E108 -> 108440 | G37: =Podsumowanie!E109 -> 65064
A38: 4.4 Personel projektu - Senior Developer | B38: =Podsumowanie!D110 -> 0 | C38: =Podsumowanie!D111 -> 0 | D38: =Podsumowanie!D112 -> 0 | E38: =Podsumowanie!E110 -> 82500 | F38: =Podsumowanie!E111 -> 82500 | G38: =Podsumowanie!E112 -> 49500
A39: 4.5 Personel projektu - Automation QA Engineer | B39: =Podsumowanie!D113 -> 0 | C39: =Podsumowanie!D114 -> 0 | D39: =Podsumowanie!D115 -> 0 | E39: =Podsumowanie!E113 -> 29760 | F39: =Podsumowanie!E114 -> 29760 | G39: =Podsumowanie!E115 -> 17856
A40: 4.6 Personel projektu - Analityk danych | B40: =Podsumowanie!D116 -> 0 | C40: =Podsumowanie!D117 -> 0 | D40: =Podsumowanie!D118 -> 0 | E40: =Podsumowanie!E116 -> 82500 | F40: =Podsumowanie!E117 -> 82500 | G40: =Podsumowanie!E118 -> 49500
...
